Workbook
Name Slicer_Type: #N/A
Name Slicer_Type1: #N/A

Sheet DASHBOARD

Sheet Analysis
B2: Automated | C2: 1135 | D2: 1135 | E2: 1126 | F2: 1019 | G2: 853 | H2: 767 | K2: AUTOMATED FUNDERS
B3: % Change | D3: =SUM(D2-C2)/C2 -> 0 | E3: =SUM(E2-D2)/D2 -> -0.0079295154 | F3: =SUM(F2-E2)/E2 -> -0.095026643 | G3: =SUM(G2-F2)/F2 -> -0.16290481 | H3: =SUM(H2-G2)/G2 -> -0.10082063 | K3: WORK Most Automated
B4: Type | C4: 2019-20 | D4: 2020-21 | E4: 2021-22 | F4: 2022-23 | G4: 2023-24 | H4: 2024-25 | K4: # | L4: 2019-20 | M4: 2020-21 | N4: 2021-22 | O4: 2022-23 | P4: 2023-24 | Q4: 2024-25
B5: Work | C5: 652 | D5: 557 | E5: 652 | F5: 664 | G5: 575 | H5: 533 | K5: 1 | L5: Kennedy Trust for Rheumatology Research | M5: Kennedy Trust for Rheumatology Research | N5: Kennedy Trust for Rheumatology Research | O5: Kennedy Trust for Rheumatology Research | P5: Kennedy Trust for Rheumatology Research | Q5: University College London
B6: % Change | D6: =SUM(D5-C5)/C5 -> -0.14570552 | E6: =SUM(E5-D5)/D5 -> 0.17055655 | F6: =SUM(F5-E5)/E5 -> 0.018404908 | G6: =SUM(G5-F5)/F5 -> -0.13403614 | H6: =SUM(H5-G5)/G5 -> -0.073043478 | K6: 2 | L6: University of Cambridge | M6: Versus Arthritis | N6: Versus Arthritis | O6: Versus Arthritis | P6: Imperial College | Q6: Imperial College
B7: Profiled | C7: 377 | D7: 404 | E7: 377 | F7: 285 | G7: 210 | H7: 179 | K7: 3 | L7: Versus Arthritis | M7: University of Cambridge | N7: University of Cambridge | O7: Oxford University Hospitals NHS Foundation Trust | P7: Versus Arthritis | Q7: Oxford University Hospitals NHS Foundation Trust
B8: % Change | D8: =SUM(D7-C7)/C7 -> 0.071618037 | E8: =SUM(E7-D7)/D7 -> -0.066831683 | F8: =SUM(F7-E7)/E7 -> -0.24403183 | G8: =SUM(G7-F7)/F7 -> -0.26315789 | H8: =SUM(H7-G7)/G7 -> -0.14761905 | K8: 4 | L8: University of York | M8: University of Leeds | N8: Royal College of Art | O8: University Hospital Southampton NHS Foundation Trust | P8: University of Liverpool | Q8: University Court of the University of Edinburgh
B9: Milestone | C9: 106 | D9: 174 | E9: 97 | F9: 70 | G9: 68 | H9: 55 | K9: 5 | L9: University of Southampton | M9: University College London | N9: Oxford University Hospitals NHS Foundation Trust | O9: University of Cambridge | P9: Oxford University Hospitals NHS Foundation Trust | Q9: University of Birmingham
B10: % Change | D10: =SUM(D9-C9)/C9 -> 0.64150943 | E10: =SUM(E9-D9)/D9 -> -0.44252874 | F10: =SUM(F9-E9)/E9 -> -0.27835052 | G10: =SUM(G9-F9)/F9 -> -0.028571429 | H10: =SUM(H9-G9)/G9 -> -0.19117647
K11: PROFILED Most Automated
K12: # | L12: 2019-20 | M12: 2020-21 | N12: 2021-22 | O12: 2022-23 | P12: 2023-24 | Q12: 2024-25
K13: 1 | L13: National Instititute for Health Research | M13: Medical Research Council | N13: Medical Research Council | O13: Novo Nordisk A/S | P13: Medical Research Council | Q13: Breakthrough Prize Foundation
K14: 2 | L14: Medical Research Council | M14: Oxford University Hospitals NHS Foundation Trust | N14: Novo Nordisk A/S | O14: Podium Analytics | P14: National Philanthropic Trust | Q14: Medical Research Council
K15: 3 | L15: AWE plc | M15: Support for the Sick Newborn and their Parents | N15: AstraZeneca UK Ltd | O15: Medical Research Council | P15: Novo Nordisk A/S | Q15: UK Biobank
K16: 4 | L16: M Suare Lasers Ltd | M16: AWE plc | N16: Janssen Research & Development, LLC | O16: AstraZeneca UK Ltd | P16: AstraZeneca UK Ltd | Q16: Podium Analytics
K17: 5 | L17: Healthcare Quality Improvement Partnership | M17: National Instititute for Health Research | N17: Wellcome Trust Sanger Institute | O17: UK Biobank | P17: Podium Analytics | Q17: Man Investments Ltd
K19: MILESTONE Most Automated
K20: # | L20: 2019-20 | M20: 2020-21 | N20: 2021-22 | O20: 2022-23 | P20: 2023-24 | Q20: 2024-25
K21: 1 | L21: Celgene Corporation | M21: Celgene Corporation | N21: Celgene Corporation | O21: Celgene Corporation | P21: Merck Sharp & Dohme Ltd
K22: 2 | L22: Department for Education | M22: DSTL | N22: Immunocore Ltd | O22: Janssen Research & Development, LLC | P22: Celgene Corporation
K23: 3 | L23: Pharmo Institute N.V. | M23: Kennedy Institute of Rheumatology | N23: Guangzhou Patronus Biotechnology Co. Ltd | O23: F Hoffmann-La Roche Ltd | P23: MCM Vaccine B.V.
K24: 4 | L24: Met Office | M24: Celgene International Sarl | N24: MCM Vaccine B.V. | O24: Merck KGaA | P24: Beijing Institute of Collaborative Innovation
K25: 5 | L25: Education Endowment Foundation | M25: Oxford University Hospitals NHS Foundation Trust | N25: Janssen Research & Development, LLC | O25: Eli Lilly and Company Ltd | P25: Heptares Therapeutics Limited
K27: AUTOMATED DEPARTMENTS
K28: WORK Most Automated
K29: # | L29: 2019-20 | M29: 2020-21 | N29: 2021-22 | O29: 2022-23 | P29: 2023-24 | Q29: 2024-25
K30: 1 | L30: Kennedy Institute of Rheumatology | M30: Kennedy Institute of Rheumatology | N30: Kennedy Institute of Rheumatology | O30: Kennedy Institute of Rheumatology | P30: Kennedy Institute of Rheumatology | Q30: Engineering Science
K31: 2 | L31: Botnar | M31: Botnar | N31: Botnar | O31: Paediatrics | P31: Paediatrics | Q31: Primary Care Health Sciences
B32: TOTAL INVOICES | C32: 0 | D32: 0 | E32: 10574 | F32: 13692 | G32: 11636 | H32: 11159 | K32: 3 | L32: Engineering Science | M32: Neurosciences | N32: Engineering Science | O32: Botnar | P32: Neurosciences | Q32: Biochemistry
B33: Cash Matching | C33: 2019-20 | D33: 2020-21 | E33: 2021-22 | F33: 2022-23 | G33: 2023-24 | H33: 2024-25 | K33: 4 | L33: Materials | M33: Engineering Science | N33: RDM Clinical Laboratory Sciences | O33: Neurosciences | P33: Tropical Medicine | Q33: Paediatrics
B34: Research Councils | C34: 0 | D34: 0 | E34: 1216 | F34: 1846 | G34: 2070 | H34: 1730 | K34: 5 | L34: Primary Care Health Sciences | M34: RDM Clinical Laboratory Sciences | N34: Neurosciences | O34: Materials | P34: Physical & Theoretical Chemistry | Q34: Neurosciences
B35: Department of Health | C35: 0 | D35: 0 | E35: 341 | F35: 593 | G35: 102 | H35: 488
B36: British Academy | C36: 0 | D36: 0 | E36: 275 | F36: 207 | G36: 144 | H36: 186 | K36: PROFILED Most Automated
B37: Royal Society | C37: 0 | D37: 0 | E37: 216 | F37: 316 | G37: 166 | H37: 244 | K37: # | L37: 2019-20 | M37: 2020-21 | N37: 2021-22 | O37: 2022-23 | P37: 2023-24 | Q37: 2024-25
B38: CRUK | C38: 0 | D38: 0 | E38: 141 | F38: 243 | G38: 297 | H38: 204 | K38: 1 | L38: Neurosciences | M38: Primary Care Health Sciences | N38: Clinical Trial Service Unit | O38: Clinical Trial Service Unit | P38: Clinical Trial Service Unit | Q38: Astrophysics
B39: Leverhulme | C39: 0 | D39: 0 | E39: 48 | F39: 154 | G39: 130 | H39: 165 | K39: 2 | L39: Department of Oncology | M39: Engineering Science | N39: Paediatrics | O39: Engineering Science | P39: RDM Investigative Medicine | Q39: Engineering Science
B40: Royal Academy of Engineering | C40: 0 | D40: 0 | E40: 23 | F40: 65 | G40: 24 | H40: 84 | K40: 3 | L40: Engineering Science | M40: Paediatrics | N40: Neurosciences | O40: Paediatrics | P40: Engineering Science | Q40: Clinical Trial Service Unit
B41: Academy of Medical Sciences | C41: 0 | D41: 0 | E41: 3 | F41: 15 | G41: 0 | H41: 18 | K41: 4 | L41: Clinical Trial Service Unit | M41: Neurosciences | N41: Department of Oncology | O41: Neurosciences | P41: Neurosciences | Q41: RDM Investigative Medicine
B42: Automated | C42: =C2 -> 1135 | D42: =D2 -> 1135 | E42: =E2 -> 1126 | F42: =F2 -> 1019 | G42: =G2 -> 853 | H42: =H2 -> 767 | K42: 5 | L42: Psychiatry | M42: Nuffield Department of Clinical Medicine | N42: Engineering Science | O42: Target Discovery Institute | P42: Paediatrics | Q42: Neurosciences
B43: Automated % | E43: =E42/SUM(E42+E44) -> 0.13548309 | F43: =F42/SUM(F42+F44) -> 0.099385546 | G43: =G42/SUM(G42+G44) -> 0.09801218 | H43: =H42/SUM(H42+H44) -> 0.09539801
...

Sheet All Invoices
A1: ALL INVOICES | M1: DEPT FREQUENCY | R1: DEPT FREQUENCY | Z1: TOTAL FIGURES
A2: ID | B2: Month | C2: Dept | D2: Project No | E2: Paying | F2: Non-Paying | G2: Invoice Amount | H2: Invoice No | I2: Type | J2: Outstanding | K2: Paid | M2: Sum of ID | N2: Column Labels
A3: 1 | B3: 45870 | C3: =LEFT(Table1[[#This Row],[Project No]],2) -> AC | D3: ACR01720 | E3: Orfonyx Bio Ltd | F3: Orfonyx Bio Ltd | G3: 99999.79 | H3: 210165056 | I3: PROFILED | J3: =SUMIF(OpenInvoices!C:C,Table1[[#This Row],[Invoice No]],OpenInvoices!N:N) -> 0 | K3: =IF(Table1[[#This Row],[Outstanding]]=0,Table1[[#This Row],[Invoice Amount]],Table1[[#This Row],[Outstanding]]-Table1[[#This Row],[Invoice Amount]]) -> 99999.79 | M3: Row Labels | N3: MILESTONE | O3: PROFILED | P3: WORK | R3: # | S3: Dept | T3: Milestone | U3: Dept | V3: Profiled | W3: Dept | X3: Work | Z3: Total Invoices | AA3: =COUNT(Table1[ID]) -> 452
A4: 1 | B4: 45870 | C4: =LEFT(Table1[[#This Row],[Project No]],2) -> BZ | D4: BZR06920 | E4: Fund for Cures UK Ltd | F4: Fund for Cures UK Ltd | G4: 139750 | H4: 210165057 | I4: PROFILED | J4: =SUMIF(OpenInvoices!C:C,Table1[[#This Row],[Invoice No]],OpenInvoices!N:N) -> 0 | K4: =IF(Table1[[#This Row],[Outstanding]]=0,Table1[[#This Row],[Invoice Amount]],Table1[[#This Row],[Outstanding]]-Table1[[#This Row],[Invoice Amount]]) -> 139750 | M4: BZ | N4: 1 | O4: 13 | P4: 39 | R4: 1 | S4: =_xlfn.XLOOKUP(T4,N:N,M:M) -> DF | T4: =LARGE(N:N,ROW(T4)-ROW(T$3)) -> 6 | U4: =_xlfn.XLOOKUP(V4,O:O,M:M) -> DF | V4: =LARGE(O:O,ROW(V4)-ROW(V$3)) -> 19 | W4: =_xlfn.XLOOKUP(X4,P:P,M:M) -> BZ | X4: =LARGE(P:P,ROW(W4)-ROW(W$3)) -> 39 | Z4: Total Amount | AA4: =SUM(Table1[Invoice Amount]) -> 27086115
A5: 1 | B5: 45870 | C5: =LEFT(Table1[[#This Row],[Project No]],2) -> CD | D5: CDR01580 | E5: Paradifference Foundation | F5: Paradifference Foundation | G5: 178436.41 | H5: 210165058 | I5: PROFILED | J5: =SUMIF(OpenInvoices!C:C,Table1[[#This Row],[Invoice No]],OpenInvoices!N:N) -> 0 | K5: =IF(Table1[[#This Row],[Outstanding]]=0,Table1[[#This Row],[Invoice Amount]],Table1[[#This Row],[Outstanding]]-Table1[[#This Row],[Invoice Amount]]) -> 178436.41 | M5: DF | N5: 6 | O5: 19 | P5: 24 | R5: 2 | S5: =_xlfn.SINGLE(_xlfn.XLOOKUP(T5,N:N,M:M)) -> CB | T5: =LARGE(N:N,ROW(T5)-ROW(T$3)) -> 2 | U5: =_xlfn.SINGLE(_xlfn.XLOOKUP(V5,O:O,M:M)) -> HF | V5: =LARGE(O:O,ROW(V5)-ROW(V$3)) -> 14 | W5: =_xlfn.SINGLE(_xlfn.XLOOKUP(X5,P:P,M:M)) -> HM | X5: =LARGE(P:P,ROW(W5)-ROW(W$3)) -> 26
A6: 1 | B6: 45870 | C6: =LEFT(Table1[[#This Row],[Project No]],2) -> CW | D6: CWR00230 | E6: Drugs for Neglected Diseases Initiative | F6: Drugs for Neglected Diseases Initiative | G6: 84000 | H6: 210165059 | I6: PROFILED | J6: =SUMIF(OpenInvoices!C:C,Table1[[#This Row],[Invoice No]],OpenInvoices!N:N) -> 0 | K6: =IF(Table1[[#This Row],[Outstanding]]=0,Table1[[#This Row],[Invoice Amount]],Table1[[#This Row],[Outstanding]]-Table1[[#This Row],[Invoice Amount]]) -> 84000 | M6: HM | O6: 4 | P6: 26 | R6: 3 | S6: =_xlfn.SINGLE(_xlfn.XLOOKUP(T6,N:N,M:M)) -> CB | T6: =LARGE(N:N,ROW(T6)-ROW(T$3)) -> 2 | U6: =_xlfn.SINGLE(_xlfn.XLOOKUP(V6,O:O,M:M)) -> BZ | V6: =LARGE(O:O,ROW(V6)-ROW(V$3)) -> 13 | W6: =_xlfn.SINGLE(_xlfn.XLOOKUP(X6,P:P,M:M)) -> DF | X6: =LARGE(P:P,ROW(W6)-ROW(W$3)) -> 24 | Z6: Milestone | AA6: =COUNTIF(Table1[Type],Z6) -> 23 | AB6: =SUMIF(Table1[Type],Z6,Table1[Invoice Amount]) -> 2958243.7
A7: 1 | B7: 45870 | C7: =LEFT(Table1[[#This Row],[Project No]],2) -> DF | D7: DFR08401 | E7: Pennine Care NHS Foundation Trust | F7: National Institute for Health Research | G7: 5972.34 | H7: 210165060 | I7: PROFILED | J7: =SUMIF(OpenInvoices!C:C,Table1[[#This Row],[Invoice No]],OpenInvoices!N:N) -> 0 | K7: =IF(Table1[[#This Row],[Outstanding]]=0,Table1[[#This Row],[Invoice Amount]],Table1[[#This Row],[Outstanding]]-Table1[[#This Row],[Invoice Amount]]) -> 5972.34 | M7: HF | N7: 1 | O7: 14 | P7: 14 | R7: 4 | S7: =_xlfn.XLOOKUP(T7,N:N,M:M) -> BZ | T7: =LARGE(N:N,ROW(T7)-ROW(T$3)) -> 1 | U7: =_xlfn.SINGLE(_xlfn.XLOOKUP(V7,O:O,M:M)) -> H7 | V7: =LARGE(O:O,ROW(V7)-ROW(V$3)) -> 10 | W7: =_xlfn.SINGLE(_xlfn.XLOOKUP(X7,P:P,M:M)) -> HF | X7: =LARGE(P:P,ROW(W7)-ROW(W$3)) -> 14 | Z7: Profiled | AA7: =COUNTIF(Table1[Type],Z7) -> 125 | AB7: =SUMIF(Table1[Type],Z7,Table1[Invoice Amount]) -> 16340215
A8: 1 | B8: 45870 | C8: =LEFT(Table1[[#This Row],[Project No]],2) -> DF | D8: DFR10800 | E8: National Centre for the Replacement, Refinement and Reduction of Animals in research (NC3RS) | F8: National Centre for the Replacement, Refinement and Reduction of Animals in research (NC3RS) | G8: 22445.47 | H8: 210165061 | I8: PROFILED | J8: =SUMIF(OpenInvoices!C:C,Table1[[#This Row],[Invoice No]],OpenInvoices!N:N) -> 0 | K8: =IF(Table1[[#This Row],[Outstanding]]=0,Table1[[#This Row],[Invoice Amount]],Table1[[#This Row],[Outstanding]]-Table1[[#This Row],[Invoice Amount]]) -> 22445.47 | M8: HJ | O8: 5 | P8: 7 | R8: 5 | S8: =_xlfn.SINGLE(_xlfn.XLOOKUP(T8,N:N,M:M)) -> BZ | T8: =LARGE(N:N,ROW(T8)-ROW(T$3)) -> 1 | U8: =_xlfn.SINGLE(_xlfn.XLOOKUP(V8,O:O,M:M)) -> HJ | V8: =LARGE(O:O,ROW(V8)-ROW(V$3)) -> 5 | W8: =_xlfn.SINGLE(_xlfn.XLOOKUP(X8,P:P,M:M)) -> HQ | X8: =LARGE(P:P,ROW(W8)-ROW(W$3)) -> 12 | Z8: Work | AA8: =COUNTIF(Table1[Type],Z8) -> 304 | AB8: =SUMIF(Table1[Type],Z8,Table1[Invoice Amount]) -> 7787656.3
A9: 1 | B9: 45870 | C9: =LEFT(Table1[[#This Row],[Project No]],2) -> DM | D9: DMR02240 | E9: Man Investments Ltd | F9: Man Investments Ltd | G9: 305000 | H9: 210165062 | I9: PROFILED | J9: =SUMIF(OpenInvoices!C:C,Table1[[#This Row],[Invoice No]],OpenInvoices!N:N) -> 0 | K9: =IF(Table1[[#This Row],[Outstanding]]=0,Table1[[#This Row],[Invoice Amount]],Table1[[#This Row],[Outstanding]]-Table1[[#This Row],[Invoice Amount]]) -> 305000 | M9: HQ | P9: 12
A10: 1 | B10: 45870 | C10: =LEFT(Table1[[#This Row],[Project No]],2) -> DN | D10: DNR01320 | E10: Oxford Transplant Foundation | F10: Oxford Transplant Foundation | G10: 10000 | H10: 210165063 | I10: PROFILED | J10: =SUMIF(OpenInvoices!C:C,Table1[[#This Row],[Invoice No]],OpenInvoices!N:N) -> 0 | K10: =IF(Table1[[#This Row],[Outstanding]]=0,Table1[[#This Row],[Invoice Amount]],Table1[[#This Row],[Outstanding]]-Table1[[#This Row],[Invoice Amount]]) -> 10000 | M10: AV | P10: 12
A11: 1 | B11: 45870 | C11: =LEFT(Table1[[#This Row],[Project No]],2) -> EP | D11: EPR02280 | E11: Oxford Transplant Foundation | F11: Oxford Transplant Foundation | G11: 9950 | H11: 210165064 | I11: PROFILED | J11: =SUMIF(OpenInvoices!C:C,Table1[[#This Row],[Invoice No]],OpenInvoices!N:N) -> 0 | K11: =IF(Table1[[#This Row],[Outstanding]]=0,Table1[[#This Row],[Invoice Amount]],Table1[[#This Row],[Outstanding]]-Table1[[#This Row],[Invoice Amount]]) -> 9950 | M11: CB | N11: 2 | O11: 1 | P11: 8
A12: 1 | B12: 45870 | C12: =LEFT(Table1[[#This Row],[Project No]],2) -> H7 | D12: H7R01210 | E12: Diabetes UK | F12: Diabetes UK | G12: 49255.11 | H12: 210165065 | I12: PROFILED | J12: =SUMIF(OpenInvoices!C:C,Table1[[#This Row],[Invoice No]],OpenInvoices!N:N) -> 0 | K12: =IF(Table1[[#This Row],[Outstanding]]=0,Table1[[#This Row],[Invoice Amount]],Table1[[#This Row],[Outstanding]]-Table1[[#This Row],[Invoice Amount]]) -> 49255.11 | M12: H7 | N12: 1 | O12: 10
A13: 1 | B13: 45870 | C13: =LEFT(Table1[[#This Row],[Project No]],2) -> H7 | D13: H7R01280 | E13: Parker-Hannifin Corporation | F13: Parker-Hannifin Corporation | G13: 1080000 | H13: 210154155 | I13: MILESTONE | J13: =SUMIF(OpenInvoices!C:C,Table1[[#This Row],[Invoice No]],OpenInvoices!N:N) -> 0 | K13: =IF(Table1[[#This Row],[Outstanding]]=0,Table1[[#This Row],[Invoice Amount]],Table1[[#This Row],[Outstanding]]-Table1[[#This Row],[Invoice Amount]]) -> 1080000 | M13: DJ | P13: 11
A14: 1 | B14: 45901 | C14: =LEFT(Table1[[#This Row],[Project No]],2) -> AC | D14: ACR01720 | E14: Natural State Ltd | F14: Natural State Ltd | G14: 76907.54 | H14: 210165718 | I14: PROFILED | J14: =SUMIF(OpenInvoices!C:C,Table1[[#This Row],[Invoice No]],OpenInvoices!N:N) -> 0 | K14: =IF(Table1[[#This Row],[Outstanding]]=0,Table1[[#This Row],[Invoice Amount]],Table1[[#This Row],[Outstanding]]-Table1[[#This Row],[Invoice Amount]]) -> 76907.54 | M14: H4 | N14: 1 | O14: 2 | P14: 7
A15: 1 | B15: 45901 | C15: =LEFT(Table1[[#This Row],[Project No]],2) -> BZ | D15: BZR06920 | E15: Pennine Care NHS Foundation Trust | F15: National Institute for Health Research | G15: 2066.18 | H15: 210165719 | I15: PROFILED | J15: =SUMIF(OpenInvoices!C:C,Table1[[#This Row],[Invoice No]],OpenInvoices!N:N) -> 0 | K15: =IF(Table1[[#This Row],[Outstanding]]=0,Table1[[#This Row],[Invoice Amount]],Table1[[#This Row],[Outstanding]]-Table1[[#This Row],[Invoice Amount]]) -> 2066.18 | M15: AZ | N15: 1 | O15: 4 | P15: 5
A16: 1 | B16: 45901 | C16: =LEFT(Table1[[#This Row],[Project No]],2) -> CD | D16: CDR01580 | E16: German Historical Institute in Rome | F16: Max Weber Foundation | G16: 60000 | H16: 210165720 | I16: PROFILED | J16: =SUMIF(OpenInvoices!C:C,Table1[[#This Row],[Invoice No]],OpenInvoices!N:N) -> 0 | K16: =IF(Table1[[#This Row],[Outstanding]]=0,Table1[[#This Row],[Invoice Amount]],Table1[[#This Row],[Outstanding]]-Table1[[#This Row],[Invoice Amount]]) -> 60000 | M16: HB | N16: 2 | P16: 8
A17: 1 | B17: 45901 | C17: =LEFT(Table1[[#This Row],[Project No]],2) -> CW | D17: CWR00230 | E17: Iuvantium Limited | F17: Iuvantium Limited | G17: 8457 | H17: 210165721 | I17: PROFILED | J17: =SUMIF(OpenInvoices!C:C,Table1[[#This Row],[Invoice No]],OpenInvoices!N:N) -> 0 | K17: =IF(Table1[[#This Row],[Outstanding]]=0,Table1[[#This Row],[Invoice Amount]],Table1[[#This Row],[Outstanding]]-Table1[[#This Row],[Invoice Amount]]) -> 8457 | M17: BL | N17: 1 | O17: 1 | P17: 8
A18: 1 | B18: 45901 | C18: =LEFT(Table1[[#This Row],[Project No]],2) -> DF | D18: DFR08401 | E18: AWE Plc | F18: AWE Plc | G18: 3750.13 | H18: 210165722 | I18: PROFILED | J18: =SUMIF(OpenInvoices!C:C,Table1[[#This Row],[Invoice No]],OpenInvoices!N:N) -> 0 | K18: =IF(Table1[[#This Row],[Outstanding]]=0,Table1[[#This Row],[Invoice Amount]],Table1[[#This Row],[Outstanding]]-Table1[[#This Row],[Invoice Amount]]) -> 3750.13 | M18: B9 | O18: 1 | P18: 7
A19: 1 | B19: 45901 | C19: =LEFT(Table1[[#This Row],[Project No]],2) -> DF | D19: DFR10800 | E19: Toyota Motor Europe NV/SA | F19: Toyota Motor Europe NV/SA | G19: 82500 | H19: 210165723 | I19: PROFILED | J19: =SUMIF(OpenInvoices!C:C,Table1[[#This Row],[Invoice No]],OpenInvoices!N:N) -> 0 | K19: =IF(Table1[[#This Row],[Outstanding]]=0,Table1[[#This Row],[Invoice Amount]],Table1[[#This Row],[Outstanding]]-Table1[[#This Row],[Invoice Amount]]) -> 82500 | M19: DC | O19: 4 | P19: 4
A20: 1 | B20: 45901 | C20: =LEFT(Table1[[#This Row],[Project No]],2) -> DM | D20: DMR02240 | E20: Kodiform Therapeutics Limited | F20: Kodiform Therapeutics Limited | G20: 261704 | H20: 210165724 | I20: PROFILED | J20: =SUMIF(OpenInvoices!C:C,Table1[[#This Row],[Invoice No]],OpenInvoices!N:N) -> 0 | K20: =IF(Table1[[#This Row],[Outstanding]]=0,Table1[[#This Row],[Invoice Amount]],Table1[[#This Row],[Outstanding]]-Table1[[#This Row],[Invoice Amount]]) -> 261704 | M20: AL | P20: 7
A21: 1 | B21: 45901 | C21: =LEFT(Table1[[#This Row],[Project No]],2) -> DN | D21: DNR01320 | E21: Omass Therapeutics Ltd | F21: Omass Therapeutics Ltd | G21: 42264.42 | H21: 210165725 | I21: PROFILED | J21: =SUMIF(OpenInvoices!C:C,Table1[[#This Row],[Invoice No]],OpenInvoices!N:N) -> 0 | K21: =IF(Table1[[#This Row],[Outstanding]]=0,Table1[[#This Row],[Invoice Amount]],Table1[[#This Row],[Outstanding]]-Table1[[#This Row],[Invoice Amount]]) -> 42264.42 | M21: DB | P21: 7
A22: 1 | B22: 45901 | C22: =LEFT(Table1[[#This Row],[Project No]],2) -> EP | D22: EPR02280 | E22: Cardiff Metropolitan University | F22: Welsh Government | G22: 5750.67 | H22: 210165726 | I22: PROFILED | J22: =SUMIF(OpenInvoices!C:C,Table1[[#This Row],[Invoice No]],OpenInvoices!N:N) -> 0 | K22: =IF(Table1[[#This Row],[Outstanding]]=0,Table1[[#This Row],[Invoice Amount]],Table1[[#This Row],[Outstanding]]-Table1[[#This Row],[Invoice Amount]]) -> 5750.67 | M22: DM | O22: 2 | P22: 5
A23: 1 | B23: 45901 | C23: =LEFT(Table1[[#This Row],[Project No]],2) -> H7 | D23: H7R01210 | E23: Diabetes UK | F23: Diabetes UK | G23: 20750.99 | H23: 210165727 | I23: PROFILED | J23: =SUMIF(OpenInvoices!C:C,Table1[[#This Row],[Invoice No]],OpenInvoices!N:N) -> 0 | K23: =IF(Table1[[#This Row],[Outstanding]]=0,Table1[[#This Row],[Invoice Amount]],Table1[[#This Row],[Outstanding]]-Table1[[#This Row],[Invoice Amount]]) -> 20750.99 | M23: DG | O23: 1 | P23: 5
A24: 1 | B24: 45901 | C24: =LEFT(Table1[[#This Row],[Project No]],2) -> H7 | D24: H7R01280 | E24: Diabetes UK | F24: Diabetes UK | G24: 120455.34 | H24: 210165728 | I24: PROFILED | J24: =SUMIF(OpenInvoices!C:C,Table1[[#This Row],[Invoice No]],OpenInvoices!N:N) -> 0 | K24: =IF(Table1[[#This Row],[Outstanding]]=0,Table1[[#This Row],[Invoice Amount]],Table1[[#This Row],[Outstanding]]-Table1[[#This Row],[Invoice Amount]]) -> 120455.34 | M24: DN | O24: 2 | P24: 4
A25: 1 | B25: 45901 | C25: =LEFT(Table1[[#This Row],[Project No]],2) -> HC | D25: HCR02250 | E25: University College London | F25: Engineering & Physical Sciences Research Council | G25: 56005.66 | H25: 210165729 | I25: PROFILED | J25: =SUMIF(OpenInvoices!C:C,Table1[[#This Row],[Invoice No]],OpenInvoices!N:N) -> 0 | K25: =IF(Table1[[#This Row],[Outstanding]]=0,Table1[[#This Row],[Invoice Amount]],Table1[[#This Row],[Outstanding]]-Table1[[#This Row],[Invoice Amount]]) -> 56005.66 | M25: DH | O25: 2 | P25: 4
A26: 1 | B26: 45901 | C26: =LEFT(Table1[[#This Row],[Project No]],2) -> HF | D26: HFR02600 | E26: South Tees Hospitals NHS Foundation Trust | F26: National Institute for Health Research | G26: 940.94 | H26: 210165730 | I26: PROFILED | J26: =SUMIF(OpenInvoices!C:C,Table1[[#This Row],[Invoice No]],OpenInvoices!N:N) -> 0 | K26: =IF(Table1[[#This Row],[Outstanding]]=0,Table1[[#This Row],[Invoice Amount]],Table1[[#This Row],[Outstanding]]-Table1[[#This Row],[Invoice Amount]]) -> 940.94 | M26: CF | O26: 1 | P26: 4
A27: 1 | B27: 45901 | C27: =LEFT(Table1[[#This Row],[Project No]],2) -> HF | D27: HFR06650 | E27: National Institute for Health Research | F27: National Institute for Health Research | G27: 6794 | H27: 210165731 | I27: PROFILED | J27: =SUMIF(OpenInvoices!C:C,Table1[[#This Row],[Invoice No]],OpenInvoices!N:N) -> 0 | K27: =IF(Table1[[#This Row],[Outstanding]]=0,Table1[[#This Row],[Invoice Amount]],Table1[[#This Row],[Outstanding]]-Table1[[#This Row],[Invoice Amount]]) -> 6794 | M27: DU | O27: 3 | P27: 2
A28: 1 | B28: 45901 | C28: =LEFT(Table1[[#This Row],[Project No]],2) -> HF | D28: HFR06670 | E28: National Institute for Health Research | F28: National Institute for Health Research | G28: 69253 | H28: 210165732 | I28: PROFILED | J28: =SUMIF(OpenInvoices!C:C,Table1[[#This Row],[Invoice No]],OpenInvoices!N:N) -> 0 | K28: =IF(Table1[[#This Row],[Outstanding]]=0,Table1[[#This Row],[Invoice Amount]],Table1[[#This Row],[Outstanding]]-Table1[[#This Row],[Invoice Amount]]) -> 69253 | M28: H6 | O28: 2 | P28: 3
A29: 1 | B29: 45901 | C29: =LEFT(Table1[[#This Row],[Project No]],2) -> HJ | D29: HJR03470 | E29: Oxford Transplant Foundation | F29: Oxford Transplant Foundation | G29: 10000 | H29: 210165733 | I29: PROFILED | J29: =SUMIF(OpenInvoices!C:C,Table1[[#This Row],[Invoice No]],OpenInvoices!N:N) -> 0 | K29: =IF(Table1[[#This Row],[Outstanding]]=0,Table1[[#This Row],[Invoice Amount]],Table1[[#This Row],[Outstanding]]-Table1[[#This Row],[Invoice Amount]]) -> 10000 | M29: CY | P29: 5
A30: 1 | B30: 45901 | C30: =LEFT(Table1[[#This Row],[Project No]],2) -> HJ | D30: HJR03480 | E30: Oxford Transplant Foundation | F30: Oxford Transplant Foundation | G30: 9621 | H30: 210165734 | I30: PROFILED | J30: =SUMIF(OpenInvoices!C:C,Table1[[#This Row],[Invoice No]],OpenInvoices!N:N) -> 0 | K30: =IF(Table1[[#This Row],[Outstanding]]=0,Table1[[#This Row],[Invoice Amount]],Table1[[#This Row],[Outstanding]]-Table1[[#This Row],[Invoice Amount]]) -> 9621 | M30: A5 | P30: 5
A31: 1 | B31: 45901 | C31: =LEFT(Table1[[#This Row],[Project No]],2) -> LC | D31: LCR00180 | E31: Citigroup Global Markets Inc | F31: Citigroup Global Markets Inc | G31: 194959 | H31: 210165735 | I31: PROFILED | J31: =SUMIF(OpenInvoices!C:C,Table1[[#This Row],[Invoice No]],OpenInvoices!N:N) -> 0 | K31: =IF(Table1[[#This Row],[Outstanding]]=0,Table1[[#This Row],[Invoice Amount]],Table1[[#This Row],[Outstanding]]-Table1[[#This Row],[Invoice Amount]]) -> 194959 | M31: EP | N31: 1 | O31: 2 | P31: 2
A32: 1 | B32: 45901 | C32: =LEFT(Table1[[#This Row],[Project No]],2) -> BL | D32: BLR02930 | E32: Celgene Corporation | F32: Celgene Corporation | G32: 68412.34 | H32: 210166040 | I32: MILESTONE | J32: =SUMIF(OpenInvoices!C:C,Table1[[#This Row],[Invoice No]],OpenInvoices!N:N) -> 68412.34 | K32: =IF(Table1[[#This Row],[Outstanding]]=0,Table1[[#This Row],[Invoice Amount]],Table1[[#This Row],[Outstanding]]-Table1[[#This Row],[Invoice Amount]]) -> 0 | M32: HN | N32: 1 | P32: 3
A33: 1 | B33: 45901 | C33: =LEFT(Table1[[#This Row],[Project No]],2) -> BZ | D33: BZR06050 | E33: ModernaTX INC | F33: ModernaTX INC | G33: 590097.62 | H33: 210166041 | I33: MILESTONE | J33: =SUMIF(OpenInvoices!C:C,Table1[[#This Row],[Invoice No]],OpenInvoices!N:N) -> 590097.62 | K33: =IF(Table1[[#This Row],[Outstanding]]=0,Table1[[#This Row],[Invoice Amount]],Table1[[#This Row],[Outstanding]]-Table1[[#This Row],[Invoice Amount]]) -> 0 | M33: DK | O33: 1 | P33: 3
A34: 1 | B34: 45901 | C34: =LEFT(Table1[[#This Row],[Project No]],2) -> CB | D34: CBR00070 | E34: Institut de recherches en science de la sante | F34: Wellcome Trust | G34: 30600 | H34: 210166042 | I34: MILESTONE | J34: =SUMIF(OpenInvoices!C:C,Table1[[#This Row],[Invoice No]],OpenInvoices!N:N) -> 30600 | K34: =IF(Table1[[#This Row],[Outstanding]]=0,Table1[[#This Row],[Invoice Amount]],Table1[[#This Row],[Outstanding]]-Table1[[#This Row],[Invoice Amount]]) -> 0 | M34: HS | N34: 1 | O34: 3
A35: 1 | B35: 45901 | C35: =LEFT(Table1[[#This Row],[Project No]],2) -> CV | D35: CVR01340 | E35: Sexual violence research initiative (SVRI) | F35: Sexual violence research initiative (SVRI) | G35: 29739.4 | H35: 210166043 | I35: MILESTONE | J35: =SUMIF(OpenInvoices!C:C,Table1[[#This Row],[Invoice No]],OpenInvoices!N:N) -> 0 | K35: =IF(Table1[[#This Row],[Outstanding]]=0,Table1[[#This Row],[Invoice Amount]],Table1[[#This Row],[Outstanding]]-Table1[[#This Row],[Invoice Amount]]) -> 29739.4 | M35: CW | O35: 4
A36: 1 | B36: 45901 | C36: =LEFT(Table1[[#This Row],[Project No]],2) -> DF | D36: DFR09730 | E36: United Kingdom National Nuclear Laboratory Limited | F36: United Kingdom National Nuclear Laboratory Limited | G36: 36280 | H36: 210166044 | I36: MILESTONE | J36: =SUMIF(OpenInvoices!C:C,Table1[[#This Row],[Invoice No]],OpenInvoices!N:N) -> 0 | K36: =IF(Table1[[#This Row],[Outstanding]]=0,Table1[[#This Row],[Invoice Amount]],Table1[[#This Row],[Outstanding]]-Table1[[#This Row],[Invoice Amount]]) -> 36280 | M36: PS | P36: 4
A37: 1 | B37: 45901 | C37: =LEFT(Table1[[#This Row],[Project No]],2) -> DF | D37: DFR09871 | E37: Met Office | F37: Met Office | G37: 25207.52 | H37: 210166045 | I37: MILESTONE | J37: =SUMIF(OpenInvoices!C:C,Table1[[#This Row],[Invoice No]],OpenInvoices!N:N) -> 0 | K37: =IF(Table1[[#This Row],[Outstanding]]=0,Table1[[#This Row],[Invoice Amount]],Table1[[#This Row],[Outstanding]]-Table1[[#This Row],[Invoice Amount]]) -> 25207.52 | M37: CZ | O37: 1 | P37: 3
A38: 1 | B38: 45901 | C38: =LEFT(Table1[[#This Row],[Project No]],2) -> DF | D38: DFR10890 | E38: Marley Health Ltd | F38: Marley Health Ltd | G38: 138418 | H38: 210166046 | I38: MILESTONE | J38: =SUMIF(OpenInvoices!C:C,Table1[[#This Row],[Invoice No]],OpenInvoices!N:N) -> 0 | K38: =IF(Table1[[#This Row],[Outstanding]]=0,Table1[[#This Row],[Invoice Amount]],Table1[[#This Row],[Outstanding]]-Table1[[#This Row],[Invoice Amount]]) -> 138418 | M38: M3 | P38: 4
A39: 1 | B39: 45901 | C39: =LEFT(Table1[[#This Row],[Project No]],2) -> DL | D39: DLR00950 | E39: Cern | F39: Cern | G39: 35240.24 | H39: 210166047 | I39: MILESTONE | J39: =SUMIF(OpenInvoices!C:C,Table1[[#This Row],[Invoice No]],OpenInvoices!N:N) -> 0 | K39: =IF(Table1[[#This Row],[Outstanding]]=0,Table1[[#This Row],[Invoice Amount]],Table1[[#This Row],[Outstanding]]-Table1[[#This Row],[Invoice Amount]]) -> 35240.24 | M39: CS | P39: 3
A40: 1 | B40: 45901 | C40: =LEFT(Table1[[#This Row],[Project No]],2) -> EP | D40: EPR02210 | E40: Bell Foundation | F40: Bell Foundation | G40: 16930.77 | H40: 210166048 | I40: MILESTONE | J40: =SUMIF(OpenInvoices!C:C,Table1[[#This Row],[Invoice No]],OpenInvoices!N:N) -> 0 | K40: =IF(Table1[[#This Row],[Outstanding]]=0,Table1[[#This Row],[Invoice Amount]],Table1[[#This Row],[Outstanding]]-Table1[[#This Row],[Invoice Amount]]) -> 16930.77 | M40: AF | P40: 3
...

Sheet Tables and Pivots
A1: INVOICES PER DEPARTMENT | F1: TOTAL PER DEPARTMENT | K1: TOTAL PER FUNDER | N1: TOP FUNDERS (slicer) | R1: TOTAL PER FUNDER | U1: TOP DEPTS (slicer) | Z1: RAISED BY MONTH | AF1: DEBT BY MONTH | AT1: DEBT BY TYPE | AV1: TOTAL | AW1: UNPAID | AX1: PAID
A2: Sum of ID | B2: Column Labels | F2: Sum of Invoice Amount | G2: Column Labels | K2: Row Labels | L2: Sum of Invoice Amount | N2: # | O2: Amount | P2: Funder | R2: Row Labels | S2: Sum of Invoice Amount | U2: # | V2: Amount | W2: Dept Code | X2: Department | Z2: MONTH | AA2: WORK | AB2: PROFILED | AC2: MILESTONE | AG2: RAISED | AH2: UNPAID | AK2: RAISED | AL2: UNPAID | AO2: RAISED | AP2: UNPAID | AT2: WORK | AU2: =SUMIF('All Invoices'!I:I,'Tables and Pivots'!AT2,'All Invoices'!J:J) -> 2119859.7 | AV2: =SUMIF('All Invoices'!I:I,'Tables and Pivots'!AT2,'All Invoices'!G:G) -> 7787656.3 | AW2: =AU2/AV2 -> 0.27220766 | AX2: =1-AW2 -> 0.72779234
A3: Row Labels | B3: MILESTONE | C3: PROFILED | D3: WORK | F3: Row Labels | G3: MILESTONE | H3: PROFILED | I3: WORK | K3: AWE Plc | L3: 68744.48 | N3: 1 | O3: =LARGE(L$3:L$1048576,ROW(O3)-ROW(O$2)) -> 1080000 | P3: =_xlfn.XLOOKUP(O3,L:L,K:K) -> Parker-Hannifin Corporation | R3: AZ | S3: 54285 | U3: 1 | V3: =LARGE(S$3:S$1048576,ROW(V3)-ROW(V$2)) -> 1080000 | W3: =_xlfn.XLOOKUP(V3,S:S,R:R) -> H7 | X3: =_xlfn.XLOOKUP(W3,Depts!A:A,Depts!B:B) -> OCDEM | Z3: 45870 | AA3: =COUNTIFS(Table1[Month],'Tables and Pivots'!$Z3,Table1[Type],'Tables and Pivots'!AA$2) -> 0 | AB3: =COUNTIFS(Table1[Month],'Tables and Pivots'!$Z3,Table1[Type],'Tables and Pivots'!AB$2) -> 10 | AC3: =COUNTIFS(Table1[Month],'Tables and Pivots'!$Z3,Table1[Type],'Tables and Pivots'!AC$2) -> 1 | AF3: MONTH | AG3: WORK | AH3: WORK | AI3: PAID | AJ3: UNPAID | AK3: PROFILED | AL3: PROFILED | AM3: PAID | AN3: UNPAID | AO3: MILESTONE | AP3: MILESTONE | AQ3: PAID | AR3: UNPAID | AT3: PROFILED | AU3: =SUMIF('All Invoices'!I:I,'Tables and Pivots'!AT3,'All Invoices'!J:J) -> 4869509 | AV3: =SUMIF('All Invoices'!I:I,'Tables and Pivots'!AT3,'All Invoices'!G:G) -> 16340215 | AW3: =AU3/AV3 -> 0.29800764 | AX3: =1-AW3 -> 0.70199236
A4: AC | C4: 3 | F4: AC | H4: 253814.88 | K4: Celgene Corporation | L4: 123789.34 | N4: 2 | O4: =LARGE(L$3:L$1048576,ROW(O4)-ROW(O$2)) -> 590097.62 | P4: =_xlfn.SINGLE(_xlfn.XLOOKUP(O4,L:L,K:K)) -> ModernaTX INC | R4: BL | S4: 68412.34 | U4: 2 | V4: =LARGE(S$3:S$1048576,ROW(V4)-ROW(V$2)) -> 590097.62 | W4: =_xlfn.SINGLE(_xlfn.XLOOKUP(V4,S:S,R:R)) -> BZ | X4: =_xlfn.XLOOKUP(W4,Depts!A:A,Depts!B:B) -> Primary Care Health Sciences | Z4: 45901 | AA4: =COUNTIFS(Table1[Month],'Tables and Pivots'!$Z4,Table1[Type],'Tables and Pivots'!AA$2) -> 55 | AB4: =COUNTIFS(Table1[Month],'Tables and Pivots'!$Z4,Table1[Type],'Tables and Pivots'!AB$2) -> 18 | AC4: =COUNTIFS(Table1[Month],'Tables and Pivots'!$Z4,Table1[Type],'Tables and Pivots'!AC$2) -> 11 | AF4: 45870 | AG4: =SUMIFS(Table1[Invoice Amount],Table1[Month],'Tables and Pivots'!AF4,Table1[Type],'Tables and Pivots'!$AG$3) -> 0 | AH4: =SUMIFS(Table1[Outstanding],Table1[Month],'Tables and Pivots'!AF4,Table1[Type],'Tables and Pivots'!$AH$3) -> 0 | AI4: =SUM(AG4-AH4)/AG4 -> #DIV/0! | AJ4: =AH4/AG4 -> #DIV/0! | AK4: =SUMIFS(Table1[Invoice Amount],Table1[Month],'Tables and Pivots'!AF4,Table1[Type],'Tables and Pivots'!$AK$3) -> 904809.12 | AL4: =SUMIFS(Table1[Outstanding],Table1[Month],'Tables and Pivots'!AF4,Table1[Type],'Tables and Pivots'!$AL$3) -> 0 | AM4: =SUM(AK4-AL4)/AK4 -> 1 | AN4: =AL4/AK4 -> 0 | AO4: =SUMIFS(Table1[Invoice Amount],Table1[Month],'Tables and Pivots'!AF4,Table1[Type],'Tables and Pivots'!$AO$3) -> 1080000 | AP4: =SUMIFS(Table1[Outstanding],Table1[Month],'Tables and Pivots'!AF4,Table1[Type],'Tables and Pivots'!$AP$3) -> 0 | AQ4: =SUM(AO4-AP4)/AO4 -> 1 | AR4: =AP4/AO4 -> 0 | AT4: MILESTONE | AU4: =SUMIF('All Invoices'!I:I,'Tables and Pivots'!AT4,'All Invoices'!J:J) -> 829829.71 | AV4: =SUMIF('All Invoices'!I:I,'Tables and Pivots'!AT4,'All Invoices'!G:G) -> 2958243.7 | AW4: =AU4/AV4 -> 0.28051432 | AX4: =1-AW4 -> 0.71948568
A5: AE | D5: 2 | F5: AE | I5: 19373.35 | K5: London School of Economics & Political Science | L5: 5000 | N5: 3 | O5: =LARGE(L$3:L$1048576,ROW(O5)-ROW(O$2)) -> 276836 | P5: =_xlfn.SINGLE(_xlfn.XLOOKUP(O5,L:L,K:K)) -> Marley Health Ltd | R5: BW | S5: 244983.81 | U5: 3 | V5: =LARGE(S$3:S$1048576,ROW(V5)-ROW(V$2)) -> 464748 | W5: =_xlfn.SINGLE(_xlfn.XLOOKUP(V5,S:S,R:R)) -> DF | X5: =_xlfn.XLOOKUP(W5,Depts!A:A,Depts!B:B) -> Engineering Science | Z5: 45931 | AA5: =COUNTIFS(Table1[Month],'Tables and Pivots'!$Z5,Table1[Type],'Tables and Pivots'!AA$2) -> 56 | AB5: =COUNTIFS(Table1[Month],'Tables and Pivots'!$Z5,Table1[Type],'Tables and Pivots'!AB$2) -> 23 | AC5: =COUNTIFS(Table1[Month],'Tables and Pivots'!$Z5,Table1[Type],'Tables and Pivots'!AC$2) -> 5 | AF5: 45901 | AG5: =SUMIFS(Table1[Invoice Amount],Table1[Month],'Tables and Pivots'!AF5,Table1[Type],'Tables and Pivots'!$AG$3) -> 1594389.1 | AH5: =SUMIFS(Table1[Outstanding],Table1[Month],'Tables and Pivots'!AF5,Table1[Type],'Tables and Pivots'!$AH$3) -> 59976.34 | AI5: =SUM(AG5-AH5)/AG5 -> 0.96238287 | AJ5: =AH5/AG5 -> 0.037617128 | AK5: =SUMIFS(Table1[Invoice Amount],Table1[Month],'Tables and Pivots'!AF5,Table1[Type],'Tables and Pivots'!$AK$3) -> 1032179.9 | AL5: =SUMIFS(Table1[Outstanding],Table1[Month],'Tables and Pivots'!AF5,Table1[Type],'Tables and Pivots'!$AL$3) -> 0 | AM5: =SUM(AK5-AL5)/AK5 -> 1 | AN5: =AL5/AK5 -> 0 | AO5: =SUMIFS(Table1[Invoice Amount],Table1[Month],'Tables and Pivots'!AF5,Table1[Type],'Tables and Pivots'!$AO$3) -> 1033802.9 | AP5: =SUMIFS(Table1[Outstanding],Table1[Month],'Tables and Pivots'!AF5,Table1[Type],'Tables and Pivots'!$AP$3) -> 751986.96 | AQ5: =SUM(AO5-AP5)/AO5 -> 0.27260122 | AR5: =AP5/AO5 -> 0.72739878 | AU5: =SUM(AU2:AU4) -> 7819198.4 | AW5: =AVERAGE(AW2:AW4) -> 0.28357654
A6: AF | D6: 3 | F6: AF | I6: 82432.85 | K6: Met Office | L6: 82887.52 | N6: 4 | O6: =LARGE(L$3:L$1048576,ROW(O6)-ROW(O$2)) -> 244983.81 | P6: =_xlfn.SINGLE(_xlfn.XLOOKUP(O6,L:L,K:K)) -> LifeArc | R6: BZ | S6: 590097.62 | U6: 4 | V6: =LARGE(S$3:S$1048576,ROW(V6)-ROW(V$2)) -> 244983.81 | W6: =_xlfn.SINGLE(_xlfn.XLOOKUP(V6,S:S,R:R)) -> BW | X6: =_xlfn.XLOOKUP(W6,Depts!A:A,Depts!B:B) -> Pharmacology | Z6: 45962 | AA6: =COUNTIFS(Table1[Month],'Tables and Pivots'!$Z6,Table1[Type],'Tables and Pivots'!AA$2) -> 32 | AB6: =COUNTIFS(Table1[Month],'Tables and Pivots'!$Z6,Table1[Type],'Tables and Pivots'!AB$2) -> 10 | AC6: =COUNTIFS(Table1[Month],'Tables and Pivots'!$Z6,Table1[Type],'Tables and Pivots'!AC$2) -> 0 | AF6: 45931 | AG6: =SUMIFS(Table1[Invoice Amount],Table1[Month],'Tables and Pivots'!AF6,Table1[Type],'Tables and Pivots'!$AG$3) -> 1815639.1 | AH6: =SUMIFS(Table1[Outstanding],Table1[Month],'Tables and Pivots'!AF6,Table1[Type],'Tables and Pivots'!$AH$3) -> 74874.41 | AI6: =SUM(AG6-AH6)/AG6 -> 0.9587614 | AJ6: =AH6/AG6 -> 0.041238597 | AK6: =SUMIFS(Table1[Invoice Amount],Table1[Month],'Tables and Pivots'!AF6,Table1[Type],'Tables and Pivots'!$AK$3) -> 4236096.4 | AL6: =SUMIFS(Table1[Outstanding],Table1[Month],'Tables and Pivots'!AF6,Table1[Type],'Tables and Pivots'!$AL$3) -> 15867.1 | AM6: =SUM(AK6-AL6)/AK6 -> 0.99625431 | AN6: =AL6/AK6 -> 0.0037456891 | AO6: =SUMIFS(Table1[Invoice Amount],Table1[Month],'Tables and Pivots'!AF6,Table1[Type],'Tables and Pivots'!$AO$3) -> 383196.23 | AP6: =SUMIFS(Table1[Outstanding],Table1[Month],'Tables and Pivots'!AF6,Table1[Type],'Tables and Pivots'!$AP$3) -> 0 | AQ6: =SUM(AO6-AP6)/AO6 -> 1 | AR6: =AP6/AO6 -> 0
A7: AJ | C7: 3 | F7: AJ | H7: 231347.22 | K7: MiroBio Ltd | L7: 54285 | N7: 5 | O7: =LARGE(L$3:L$1048576,ROW(O7)-ROW(O$2)) -> 123789.34 | P7: =_xlfn.SINGLE(_xlfn.XLOOKUP(O7,L:L,K:K)) -> Celgene Corporation | R7: CV | S7: 29739.4 | U7: 5 | V7: =LARGE(S$3:S$1048576,ROW(V7)-ROW(V$2)) -> 133801.85 | W7: =_xlfn.SINGLE(_xlfn.XLOOKUP(V7,S:S,R:R)) -> CB | X7: =_xlfn.XLOOKUP(W7,Depts!A:A,Depts!B:B) -> Biology | Z7: 45992 | AA7: =COUNTIFS(Table1[Month],'Tables and Pivots'!$Z7,Table1[Type],'Tables and Pivots'!AA$2) -> 32 | AB7: =COUNTIFS(Table1[Month],'Tables and Pivots'!$Z7,Table1[Type],'Tables and Pivots'!AB$2) -> 7 | AC7: =COUNTIFS(Table1[Month],'Tables and Pivots'!$Z7,Table1[Type],'Tables and Pivots'!AC$2) -> 0 | AF7: 45962 | AG7: =SUMIFS(Table1[Invoice Amount],Table1[Month],'Tables and Pivots'!AF7,Table1[Type],'Tables and Pivots'!$AG$3) -> 627656.46 | AH7: =SUMIFS(Table1[Outstanding],Table1[Month],'Tables and Pivots'!AF7,Table1[Type],'Tables and Pivots'!$AH$3) -> 194162.7 | AI7: =SUM(AG7-AH7)/AG7 -> 0.6906545 | AJ7: =AH7/AG7 -> 0.3093455 | AK7: =SUMIFS(Table1[Invoice Amount],Table1[Month],'Tables and Pivots'!AF7,Table1[Type],'Tables and Pivots'!$AK$3) -> 1855885.9 | AL7: =SUMIFS(Table1[Outstanding],Table1[Month],'Tables and Pivots'!AF7,Table1[Type],'Tables and Pivots'!$AL$3) -> 0 | AM7: =SUM(AK7-AL7)/AK7 -> 1 | AN7: =AL7/AK7 -> 0 | AO7: =SUMIFS(Table1[Invoice Amount],Table1[Month],'Tables and Pivots'!AF7,Table1[Type],'Tables and Pivots'!$AO$3) -> 0 | AP7: =SUMIFS(Table1[Outstanding],Table1[Month],'Tables and Pivots'!AF7,Table1[Type],'Tables and Pivots'!$AP$3) -> 0 | AQ7: =SUM(AO7-AP7)/AO7 -> #DIV/0! | AR7: =AP7/AO7 -> #DIV/0!
A8: AL | D8: 7 | F8: AL | I8: 460100.38 | K8: University of Cambridge | L8: 103201.85 | R8: DF | S8: 464748 | Z8: 46023 | AA8: =COUNTIFS(Table1[Month],'Tables and Pivots'!$Z8,Table1[Type],'Tables and Pivots'!AA$2) -> 65 | AB8: =COUNTIFS(Table1[Month],'Tables and Pivots'!$Z8,Table1[Type],'Tables and Pivots'!AB$2) -> 31 | AC8: =COUNTIFS(Table1[Month],'Tables and Pivots'!$Z8,Table1[Type],'Tables and Pivots'!AC$2) -> 3 | AF8: 45992 | AG8: =SUMIFS(Table1[Invoice Amount],Table1[Month],'Tables and Pivots'!AF8,Table1[Type],'Tables and Pivots'!$AG$3) -> 621094.45 | AH8: =SUMIFS(Table1[Outstanding],Table1[Month],'Tables and Pivots'!AF8,Table1[Type],'Tables and Pivots'!$AH$3) -> 134752.77 | AI8: =SUM(AG8-AH8)/AG8 -> 0.78303981 | AJ8: =AH8/AG8 -> 0.21696019 | AK8: =SUMIFS(Table1[Invoice Amount],Table1[Month],'Tables and Pivots'!AF8,Table1[Type],'Tables and Pivots'!$AK$3) -> 379263.78 | AL8: =SUMIFS(Table1[Outstanding],Table1[Month],'Tables and Pivots'!AF8,Table1[Type],'Tables and Pivots'!$AL$3) -> 22817.17 | AM8: =SUM(AK8-AL8)/AK8 -> 0.93983826 | AN8: =AL8/AK8 -> 0.060161743 | AO8: =SUMIFS(Table1[Invoice Amount],Table1[Month],'Tables and Pivots'!AF8,Table1[Type],'Tables and Pivots'!$AO$3) -> 0 | AP8: =SUMIFS(Table1[Outstanding],Table1[Month],'Tables and Pivots'!AF8,Table1[Type],'Tables and Pivots'!$AP$3) -> 0 | AQ8: =SUM(AO8-AP8)/AO8 -> #DIV/0! | AR8: =AP8/AO8 -> #DIV/0!
A9: AM | C9: 2 | F9: AM | H9: 435715.12 | K9: Liverpool School of Tropical Medicine | L9: 11162.75 | R9: EP | S9: 16930.77 | Z9: 46054 | AA9: =COUNTIFS(Table1[Month],'Tables and Pivots'!$Z9,Table1[Type],'Tables and Pivots'!AA$2) -> 24 | AB9: =COUNTIFS(Table1[Month],'Tables and Pivots'!$Z9,Table1[Type],'Tables and Pivots'!AB$2) -> 12 | AC9: =COUNTIFS(Table1[Month],'Tables and Pivots'!$Z9,Table1[Type],'Tables and Pivots'!AC$2) -> 3 | AF9: 46023 | AG9: =SUMIFS(Table1[Invoice Amount],Table1[Month],'Tables and Pivots'!AF9,Table1[Type],'Tables and Pivots'!$AG$3) -> 2044413.2 | AH9: =SUMIFS(Table1[Outstanding],Table1[Month],'Tables and Pivots'!AF9,Table1[Type],'Tables and Pivots'!$AH$3) -> 797908.12 | AI9: =SUM(AG9-AH9)/AG9 -> 0.6097129 | AJ9: =AH9/AG9 -> 0.3902871 | AK9: =SUMIFS(Table1[Invoice Amount],Table1[Month],'Tables and Pivots'!AF9,Table1[Type],'Tables and Pivots'!$AK$3) -> 4676851 | AL9: =SUMIFS(Table1[Outstanding],Table1[Month],'Tables and Pivots'!AF9,Table1[Type],'Tables and Pivots'!$AL$3) -> 2015181.4 | AM9: =SUM(AK9-AL9)/AK9 -> 0.56911577 | AN9: =AL9/AK9 -> 0.43088423 | AO9: =SUMIFS(Table1[Invoice Amount],Table1[Month],'Tables and Pivots'!AF9,Table1[Type],'Tables and Pivots'!$AO$3) -> 313826.56 | AP9: =SUMIFS(Table1[Outstanding],Table1[Month],'Tables and Pivots'!AF9,Table1[Type],'Tables and Pivots'!$AP$3) -> 68842.75 | AQ9: =SUM(AO9-AP9)/AO9 -> 0.78063441 | AR9: =AP9/AO9 -> 0.21936559
A10: AP | D10: 1 | F10: AP | I10: 1549.06 | K10: Institut de recherches en science de la sante | L10: 30600 | R10: H4 | S10: 56964.9 | Z10: 46082 | AA10: =COUNTIFS(Table1[Month],'Tables and Pivots'!$Z10,Table1[Type],'Tables and Pivots'!AA$2) -> 40 | AB10: =COUNTIFS(Table1[Month],'Tables and Pivots'!$Z10,Table1[Type],'Tables and Pivots'!AB$2) -> 14 | AC10: =COUNTIFS(Table1[Month],'Tables and Pivots'!$Z10,Table1[Type],'Tables and Pivots'!AC$2) -> 0 | AF10: 46054 | AG10: =SUMIFS(Table1[Invoice Amount],Table1[Month],'Tables and Pivots'!AF10,Table1[Type],'Tables and Pivots'!$AG$3) -> 447225.59 | AH10: =SUMIFS(Table1[Outstanding],Table1[Month],'Tables and Pivots'!AF10,Table1[Type],'Tables and Pivots'!$AH$3) -> 220947.06 | AI10: =SUM(AG10-AH10)/AG10 -> 0.5059606 | AJ10: =AH10/AG10 -> 0.4940394 | AK10: =SUMIFS(Table1[Invoice Amount],Table1[Month],'Tables and Pivots'!AF10,Table1[Type],'Tables and Pivots'!$AK$3) -> 1406322.9 | AL10: =SUMIFS(Table1[Outstanding],Table1[Month],'Tables and Pivots'!AF10,Table1[Type],'Tables and Pivots'!$AL$3) -> 1000587.2 | AM10: =SUM(AK10-AL10)/AK10 -> 0.28850823 | AN10: =AL10/AK10 -> 0.71149177 | AO10: =SUMIFS(Table1[Invoice Amount],Table1[Month],'Tables and Pivots'!AF10,Table1[Type],'Tables and Pivots'!$AO$3) -> 147418 | AP10: =SUMIFS(Table1[Outstanding],Table1[Month],'Tables and Pivots'!AF10,Table1[Type],'Tables and Pivots'!$AP$3) -> 9000 | AQ10: =SUM(AO10-AP10)/AO10 -> 0.93894911 | AR10: =AP10/AO10 -> 0.061050889
A11: AV | D11: 12 | F11: AV | I11: 223215.9 | K11: Cern | L11: 35240.24 | R11: H7 | S11: 1080000 | Z11: 46113 | AA11: =COUNTIFS(Table1[Month],'Tables and Pivots'!$Z11,Table1[Type],'Tables and Pivots'!AA$2) -> 0 | AB11: =COUNTIFS(Table1[Month],'Tables and Pivots'!$Z11,Table1[Type],'Tables and Pivots'!AB$2) -> 0 | AC11: =COUNTIFS(Table1[Month],'Tables and Pivots'!$Z11,Table1[Type],'Tables and Pivots'!AC$2) -> 0 | AF11: 46082 | AG11: =SUMIFS(Table1[Invoice Amount],Table1[Month],'Tables and Pivots'!AF11,Table1[Type],'Tables and Pivots'!$AG$3) -> 637238.31 | AH11: =SUMIFS(Table1[Outstanding],Table1[Month],'Tables and Pivots'!AF11,Table1[Type],'Tables and Pivots'!$AH$3) -> 637238.31 | AI11: =SUM(AG11-AH11)/AG11 -> 0 | AJ11: =AH11/AG11 -> 1 | AK11: =SUMIFS(Table1[Invoice Amount],Table1[Month],'Tables and Pivots'!AF11,Table1[Type],'Tables and Pivots'!$AK$3) -> 1848806.2 | AL11: =SUMIFS(Table1[Outstanding],Table1[Month],'Tables and Pivots'!AF11,Table1[Type],'Tables and Pivots'!$AL$3) -> 1815056.2 | AM11: =SUM(AK11-AL11)/AK11 -> 0.018255023 | AN11: =AL11/AK11 -> 0.98174498 | AO11: =SUMIFS(Table1[Invoice Amount],Table1[Month],'Tables and Pivots'!AF11,Table1[Type],'Tables and Pivots'!$AO$3) -> 0 | AP11: =SUMIFS(Table1[Outstanding],Table1[Month],'Tables and Pivots'!AF11,Table1[Type],'Tables and Pivots'!$AP$3) -> 0 | AQ11: =SUM(AO11-AP11)/AO11 -> #DIV/0! | AR11: =AP11/AO11 -> #DIV/0!
A12: AZ | B12: 1 | C12: 4 | D12: 5 | F12: AZ | G12: 54285 | H12: 429818.85 | I12: 96606.1 | K12: LifeArc | L12: 244983.81 | R12: HB | S12: 11500 | Z12: 46143 | AA12: =COUNTIFS(Table1[Month],'Tables and Pivots'!$Z12,Table1[Type],'Tables and Pivots'!AA$2) -> 0 | AB12: =COUNTIFS(Table1[Month],'Tables and Pivots'!$Z12,Table1[Type],'Tables and Pivots'!AB$2) -> 0 | AC12: =COUNTIFS(Table1[Month],'Tables and Pivots'!$Z12,Table1[Type],'Tables and Pivots'!AC$2) -> 0 | AF12: 46113 | AG12: =SUMIFS(Table1[Invoice Amount],Table1[Month],'Tables and Pivots'!AF12,Table1[Type],'Tables and Pivots'!$AG$3) -> 0 | AH12: =SUMIFS(Table1[Outstanding],Table1[Month],'Tables and Pivots'!AF12,Table1[Type],'Tables and Pivots'!$AH$3) -> 0 | AI12: =SUM(AG12-AH12)/AG12 -> #DIV/0! | AJ12: =AH12/AG12 -> #DIV/0! | AK12: =SUMIFS(Table1[Invoice Amount],Table1[Month],'Tables and Pivots'!AF12,Table1[Type],'Tables and Pivots'!$AK$3) -> 0 | AL12: =SUMIFS(Table1[Outstanding],Table1[Month],'Tables and Pivots'!AF12,Table1[Type],'Tables and Pivots'!$AL$3) -> 0 | AM12: =SUM(AK12-AL12)/AK12 -> #DIV/0! | AN12: =AL12/AK12 -> #DIV/0! | AO12: =SUMIFS(Table1[Invoice Amount],Table1[Month],'Tables and Pivots'!AF12,Table1[Type],'Tables and Pivots'!$AO$3) -> 0 | AP12: =SUMIFS(Table1[Outstanding],Table1[Month],'Tables and Pivots'!AF12,Table1[Type],'Tables and Pivots'!$AP$3) -> 0 | AQ12: =SUM(AO12-AP12)/AO12 -> #DIV/0! | AR12: =AP12/AO12 -> #DIV/0!
A13: B8 | C13: 1 | F13: B8 | H13: 26250 | K13: PSC Support | L13: 11500 | R13: HF | S13: 100000 | Z13: 46174 | AA13: =COUNTIFS(Table1[Month],'Tables and Pivots'!$Z13,Table1[Type],'Tables and Pivots'!AA$2) -> 0 | AB13: =COUNTIFS(Table1[Month],'Tables and Pivots'!$Z13,Table1[Type],'Tables and Pivots'!AB$2) -> 0 | AC13: =COUNTIFS(Table1[Month],'Tables and Pivots'!$Z13,Table1[Type],'Tables and Pivots'!AC$2) -> 0 | AF13: 46143 | AG13: =SUMIFS(Table1[Invoice Amount],Table1[Month],'Tables and Pivots'!AF13,Table1[Type],'Tables and Pivots'!$AG$3) -> 0 | AH13: =SUMIFS(Table1[Outstanding],Table1[Month],'Tables and Pivots'!AF13,Table1[Type],'Tables and Pivots'!$AH$3) -> 0 | AI13: =SUM(AG13-AH13)/AG13 -> #DIV/0! | AJ13: =AH13/AG13 -> #DIV/0! | AK13: =SUMIFS(Table1[Invoice Amount],Table1[Month],'Tables and Pivots'!AF13,Table1[Type],'Tables and Pivots'!$AK$3) -> 0 | AL13: =SUMIFS(Table1[Outstanding],Table1[Month],'Tables and Pivots'!AF13,Table1[Type],'Tables and Pivots'!$AL$3) -> 0 | AM13: =SUM(AK13-AL13)/AK13 -> #DIV/0! | AN13: =AL13/AK13 -> #DIV/0! | AO13: =SUMIFS(Table1[Invoice Amount],Table1[Month],'Tables and Pivots'!AF13,Table1[Type],'Tables and Pivots'!$AO$3) -> 0 | AP13: =SUMIFS(Table1[Outstanding],Table1[Month],'Tables and Pivots'!AF13,Table1[Type],'Tables and Pivots'!$AP$3) -> 0 | AQ13: =SUM(AO13-AP13)/AO13 -> #DIV/0! | AR13: =AP13/AO13 -> #DIV/0!
A14: B9 | C14: 1 | D14: 7 | F14: B9 | H14: 84000 | I14: 125523.49 | K14: Bell Foundation | L14: 16930.77 | R14: HN | S14: 11162.75 | Z14: 46204 | AA14: =COUNTIFS(Table1[Month],'Tables and Pivots'!$Z14,Table1[Type],'Tables and Pivots'!AA$2) -> 0 | AB14: =COUNTIFS(Table1[Month],'Tables and Pivots'!$Z14,Table1[Type],'Tables and Pivots'!AB$2) -> 0 | AC14: =COUNTIFS(Table1[Month],'Tables and Pivots'!$Z14,Table1[Type],'Tables and Pivots'!AC$2) -> 0 | AF14: 46174 | AG14: =SUMIFS(Table1[Invoice Amount],Table1[Month],'Tables and Pivots'!AF14,Table1[Type],'Tables and Pivots'!$AG$3) -> 0 | AH14: =SUMIFS(Table1[Outstanding],Table1[Month],'Tables and Pivots'!AF14,Table1[Type],'Tables and Pivots'!$AH$3) -> 0 | AI14: =SUM(AG14-AH14)/AG14 -> #DIV/0! | AJ14: =AH14/AG14 -> #DIV/0! | AK14: =SUMIFS(Table1[Invoice Amount],Table1[Month],'Tables and Pivots'!AF14,Table1[Type],'Tables and Pivots'!$AK$3) -> 0 | AL14: =SUMIFS(Table1[Outstanding],Table1[Month],'Tables and Pivots'!AF14,Table1[Type],'Tables and Pivots'!$AL$3) -> 0 | AM14: =SUM(AK14-AL14)/AK14 -> #DIV/0! | AN14: =AL14/AK14 -> #DIV/0! | AO14: =SUMIFS(Table1[Invoice Amount],Table1[Month],'Tables and Pivots'!AF14,Table1[Type],'Tables and Pivots'!$AO$3) -> 0 | AP14: =SUMIFS(Table1[Outstanding],Table1[Month],'Tables and Pivots'!AF14,Table1[Type],'Tables and Pivots'!$AP$3) -> 0 | AQ14: =SUM(AO14-AP14)/AO14 -> #DIV/0! | AR14: =AP14/AO14 -> #DIV/0!
A15: BB | C15: 1 | D15: 1 | F15: BB | H15: 125000 | I15: 1299.5 | K15: Parker-Hannifin Corporation | L15: 1080000 | R15: HS | S15: 55377 | AF15: 46204 | AG15: =SUMIFS(Table1[Invoice Amount],Table1[Month],'Tables and Pivots'!AF15,Table1[Type],'Tables and Pivots'!$AG$3) -> 0 | AH15: =SUMIFS(Table1[Outstanding],Table1[Month],'Tables and Pivots'!AF15,Table1[Type],'Tables and Pivots'!$AH$3) -> 0 | AI15: =SUM(AG15-AH15)/AG15 -> #DIV/0! | AJ15: =AH15/AG15 -> #DIV/0! | AK15: =SUMIFS(Table1[Invoice Amount],Table1[Month],'Tables and Pivots'!AF15,Table1[Type],'Tables and Pivots'!$AK$3) -> 0 | AL15: =SUMIFS(Table1[Outstanding],Table1[Month],'Tables and Pivots'!AF15,Table1[Type],'Tables and Pivots'!$AL$3) -> 0 | AM15: =SUM(AK15-AL15)/AK15 -> #DIV/0! | AN15: =AL15/AK15 -> #DIV/0! | AO15: =SUMIFS(Table1[Invoice Amount],Table1[Month],'Tables and Pivots'!AF15,Table1[Type],'Tables and Pivots'!$AO$3) -> 0 | AP15: =SUMIFS(Table1[Outstanding],Table1[Month],'Tables and Pivots'!AF15,Table1[Type],'Tables and Pivots'!$AP$3) -> 0 | AQ15: =SUM(AO15-AP15)/AO15 -> #DIV/0! | AR15: =AP15/AO15 -> #DIV/0!
A16: BK | D16: 3 | F16: BK | I16: 39258.84 | K16: ModernaTX INC | L16: 590097.62 | R16: DL | S16: 35240.24
A17: BL | B17: 1 | C17: 1 | D17: 8 | F17: BL | G17: 68412.34 | H17: 370370.37 | I17: 371760.09 | K17: Sexual violence research initiative (SVRI) | L17: 29739.4 | R17: CB | S17: 133801.85
A18: BV | D18: 2 | F18: BV | I18: 116572.76 | K18: United Kingdom National Nuclear Laboratory Limited | L18: 36280 | R18: MQ | S18: 5000
A19: BW | B19: 1 | D19: 2 | F19: BW | G19: 244983.81 | I19: 29664.82 | K19: Marley Health Ltd | L19: 276836
A20: BX | C20: 2 | D20: 1 | F20: BX | H20: 27832.12 | I20: 3242.95 | K20: Yellowstone Biosciences Limited | L20: 56964.9
A21: BZ | B21: 1 | C21: 13 | D21: 39 | F21: BZ | G21: 590097.62 | H21: 447890.22 | I21: 1127208.5 | K21: K36 Therapeutics, Inc. | L21: 100000
A22: CD | C22: 3 | F22: CD | H22: 313436.41
A23: CF | C23: 1 | D23: 4 | F23: CF | H23: 773750 | I23: 73869.28
A24: CQ | D24: 3 | F24: CQ | I24: 16547.01
A25: CS | D25: 3 | F25: CS | I25: 54993.82
A26: CV | B26: 1 | D26: 2 | F26: CV | G26: 29739.4 | I26: 13078.44
A27: CZ | C27: 1 | D27: 3 | F27: CZ | H27: 5481.18 | I27: 53158.59
A28: DB | D28: 7 | F28: DB | I28: 117348.25
A29: DC | C29: 4 | D29: 4 | F29: DC | H29: 35000 | I29: 75072.26
A30: DF | B30: 6 | C30: 19 | D30: 24 | F30: DF | G30: 464748 | H30: 3970658.2 | I30: 1074890
A31: DG | C31: 1 | D31: 5 | F31: DG | H31: 25000 | I31: 9600.84
A32: DH | C32: 2 | D32: 4 | F32: DH | H32: 32871 | I32: 90452.17
A33: DJ | D33: 11 | F33: DJ | I33: 423634.16
A34: DK | C34: 1 | D34: 3 | F34: DK | H34: 500000 | I34: 10687.86
A35: DM | C35: 2 | D35: 5 | F35: DM | H35: 566704 | I35: 85645.89
A36: DN | C36: 2 | D36: 4 | F36: DN | H36: 52264.42 | I36: 136489.67
A37: DQ | C37: 1 | F37: DQ | H37: 104166.67
A38: DR | D38: 1 | F38: DR | I38: 24704.25
A39: DU | C39: 3 | D39: 2 | F39: DU | H39: 105223.47 | I39: 61626.64
A40: EB | D40: 1 | F40: EB | I40: 14932.77
...

Sheet Depts
A1: Code | B1: Department Name
A2: A3 | B2: IDRM- Paediatrics
A3: A4 | B3: Institute of Developmental and Regenerative Medicine
A4: A5 | B4: DPAG Bionanoscience
A5: A9 | B5: Kenya (Trop Med)
A6: AB | B6: Pitt Rivers Museum
A7: AC | B7: School of Geography and the Environment
A8: AE | B8: Social & Cultural Anthropology
A9: AF | B9: Environmental Change Institute
A10: AJ | B10: Target Discovery Institute
A11: AL | B11: Biochemistry
A12: AM | B12: Statistics
... A127: YS | B127: Uehiro Institute

Sheet OpenInvoices
A1: Sponsor | B1: Sponsor Account | C1: Invoice Number | D1: Invoice Date | E1: Due Date | F1: Today | G1: Days Overdue | H1: Ageing Bucket | I1: Currency | J1: Invoice Amount Inv Curr | K1: Vat Amount Inv Curr | L1: Amount Remaining Inv Curr | M1: Vat Remaining Gbp | N1: Actual Outstanding | O1: Amount Remaining GBP | P1: Project Number | Q1: Project Name | R1: Project Type | S1: Project Status | T1: Project Department | U1: Principal Investigator | V1: Invoice Comments | W1: Customer Order Number
A2: M Squared Lasers Ltd | B2: 74596 | C2: 210084653 | D2: 43832 | E2: 43862 | F2: 46091 | G2: 2229 | H2: 360+ days overdue | I2: GBP | J2: 3836.57 | K2: 639.43 | L2: 2692.56 | M2: 448.76 | N2: =IF(I2="GBP",L2-K2,O2-K2) -> 2053.13 | O2: 2692.56 | P2: BWR00971 | Q2: M Squared/Emptage KTP | R2: Research | S2: Pending Close | T2: Pharmacology | U2: Emptage, Prof. Nigel | V2: g- 16/07/25 email from Graeme - We would pay £4895 in first 2 weeks of August then £10k per month Sept-Dec. Could that work to get this finished off. 17/07/25 email to Graeme - Thanks for your email, yes that will work and agree to this payment plan. 27/08/25 email to Graeme - Can you let me know if the initial payment of £4,895.00 has been made? 24/09/25 email to Graeme Malcolm - Have you and update on when we will receive the expected payments. 29/10/25 email from Jimmy (dept) to James B - Would it be worth my PI who worked with them getting in touch? I will reach out to him now. 01/12/2025 email from James B to Heidi (dept) - For BWR00971, we haven’t yet created a specific provision for this debt. I would like to set up a departmental provision for this, £36,674.68 as calculated below, charged to BW0000, when we compile our Q2 bad debt provision. Would this be acceptable to you? 01/12/2025 email from Heidi to James - Many thanks for both of your replies, much appreciated. The dept is happy to accept your suggestions re both debts. Please let us know if you need us to do anything else, pending any provision we add to our Q2 figures. 02/12/2025 email from James to Heidi - Many thanks for getting back to me Heidi. We’ll create the agreed provisions during our usual quarterly BDP process, in early Feb 2026 (for the Jan-26 books). No further action required from you on this point. 21/01/2026 email to Graeme Malcolm - We are yet to receive any payments per your email can you let me know when payment will begin. | W2: KTP010823
A3: OxStem Immuno | B3: 75563 | C3: 210085688 | D3: 43843 | E3: 43873 | F3: 46091 | G3: 2218 | H3: 360+ days overdue | I3: GBP | J3: 37237.97 | K3: 6206.33 | L3: 37237.97 | M3: 6206.33 | N3: =IF(I3="GBP",L3-K3,O3-K3) -> 31031.64 | O3: 37237.97 | P3: BVR01440 | Q3: Greaves - OxStem | R3: Research | S3: Pending Close | T3: Dunn School of Pathology | U3: Greaves, Prof. David | V3: g- 22/08/24 email from Robert Bough to Stephen - The Company is still disputing parts of the invoices, and we continue to rebut their arguments. Angela Lintern is completely up to speed with the latest position.
A4: Oxstem Oncology Ltd | B4: 70397 | C4: 210086645 | D4: 43861 | E4: 43891 | F4: 46091 | G4: 2200 | H4: 360+ days overdue | I4: GBP | J4: 172095.46 | K4: 28682.58 | L4: 172095.46 | M4: 28682.58 | N4: =IF(I4="GBP",L4-K4,O4-K4) -> 143412.88 | O4: 172095.46 | P4: DMR00830 | Q4: Oxstem Oncology | R4: Research | S4: Pending Close | T4: Organic Chemistry | U4: Russell, Prof. Angela | V4: g- 22/08/24 email from Robert Bough to Stephen - The Company is still disputing parts of the invoices, and we continue to rebut their arguments. Angela Lintern is completely up to speed with the latest position. | W4: N/A
A5: Oxstem Ltd | B5: 70393 | C5: 210086643 | D5: 43861 | E5: 43891 | F5: 46091 | G5: 2200 | H5: 360+ days overdue | I5: GBP | J5: 16789.2 | K5: 2798.2 | L5: 16789.2 | M5: 2798.2 | N5: =IF(I5="GBP",L5-K5,O5-K5) -> 13991 | O5: 16789.2 | P5: DMR00820 | Q5: OxStem 4D -single cell culture | R5: Research | S5: Pending Close | T5: Organic Chemistry | U5: Russell, Prof. Angela | V5: g- 22/08/24 email from Robert Bough to Stephen - The Company is still disputing parts of the invoices, and we continue to rebut their arguments. Angela Lintern is completely up to speed with the latest position. | W5: N/A
A6: OxStem Neuro Ltd | B6: 70872 | C6: 210086650 | D6: 43861 | E6: 43891 | F6: 46091 | G6: 2200 | H6: 360+ days overdue | I6: GBP | J6: 296447.64 | K6: 49407.94 | L6: 296447.64 | M6: 49407.94 | N6: =IF(I6="GBP",L6-K6,O6-K6) -> 247039.7 | O6: 296447.64 | P6: DMR00870 | Q6: OxStem Neuro | R6: Research | S6: Pending Close | T6: Organic Chemistry | U6: Russell, Prof. Angela | V6: g- 22/08/24 email from Robert Bough to Stephen - The Company is still disputing parts of the invoices, and we continue to rebut their arguments. Angela Lintern is completely up to speed with the latest position. | W6: N/A
A7: Oxstem Cardio Limited | B7: 71939 | C7: 210086652 | D7: 43861 | E7: 43891 | F7: 46091 | G7: 2200 | H7: 360+ days overdue | I7: GBP | J7: 356133.34 | K7: 59355.56 | L7: 356133.34 | M7: 59355.56 | N7: =IF(I7="GBP",L7-K7,O7-K7) -> 296777.78 | O7: 356133.34 | P7: DMR00970 | Q7: OxStem Cardio | R7: Research | S7: Pending Close | T7: Organic Chemistry | U7: Russell, Prof. Angela | V7: g- 22/08/24 email from Robert Bough to Stephen - The Company is still disputing parts of the invoices, and we continue to rebut their arguments. Angela Lintern is completely up to speed with the latest position.
A8: M Squared Lasers Ltd | B8: 74596 | C8: 210086738 | D8: 43865 | E8: 43895 | F8: 46091 | G8: 2196 | H8: 360+ days overdue | I8: GBP | J8: 3836.57 | K8: 639.43 | L8: 3836.57 | M8: 639.43 | N8: =IF(I8="GBP",L8-K8,O8-K8) -> 3197.14 | O8: 3836.57 | P8: BWR00971 | Q8: M Squared/Emptage KTP | R8: Research | S8: Pending Close | T8: Pharmacology | U8: Emptage, Prof. Nigel | V8: g- 16/07/25 email from Graeme - We would pay £4895 in first 2 weeks of August then £10k per month Sept-Dec. Could that work to get this finished off. 17/07/25 email to Graeme - Thanks for your email, yes that will work and agree to this payment plan. 27/08/25 email to Graeme - Can you let me know if the initial payment of £4,895.00 has been made? 24/09/25 email to Graeme Malcolm - Have you and update on when we will receive the expected payments. 29/10/25 email from Jimmy (dept) to James B - Would it be worth my PI who worked with them getting in touch? I will reach out to him now. 01/12/2025 email from James B to Heidi (dept) - For BWR00971, we haven’t yet created a specific provision for this debt. I would like to set up a departmental provision for this, £36,674.68 as calculated below, charged to BW0000, when we compile our Q2 bad debt provision. Would this be acceptable to you? 01/12/2025 email from Heidi to James - Many thanks for both of your replies, much appreciated. The dept is happy to accept your suggestions re both debts. Please let us know if you need us to do anything else, pending any provision we add to our Q2 figures. 02/12/2025 email from James to Heidi - Many thanks for getting back to me Heidi. We’ll create the agreed provisions during our usual quarterly BDP process, in early Feb 2026 (for the Jan-26 books). No further action required from you on this point. 21/01/2026 email to Graeme Malcolm - We are yet to receive any payments per your email can you let me know when payment will begin. | W8: KTP010823
